2023-05-09 09:39:08,065 ERROR: Exception on /search [POST] [in /Applications/anaconda3/lib/python3.9/site-packages/flask/app.py:1741]
Traceback (most recent call last):
  File "/Applications/anaconda3/lib/python3.9/site-packages/sqlalchemy/engine/base.py", line 1808, in _execute_context
    self.dialect.do_execute(
  File "/Applications/anaconda3/lib/python3.9/site-packages/sqlalchemy/engine/default.py", line 732, in do_execute
    cursor.execute(statement, parameters)
sqlite3.OperationalError: near "UNION": syntax error

The above exception was the direct cause of the following exception:

Traceback (most recent call last):
  File "/Applications/anaconda3/lib/python3.9/site-packages/flask/app.py", line 2525, in wsgi_app
    response = self.full_dispatch_request()
  File "/Applications/anaconda3/lib/python3.9/site-packages/flask/app.py", line 1822, in full_dispatch_request
    rv = self.handle_user_exception(e)
  File "/Applications/anaconda3/lib/python3.9/site-packages/flask/app.py", line 1820, in full_dispatch_request
    rv = self.dispatch_request()
  File "/Applications/anaconda3/lib/python3.9/site-packages/flask/app.py", line 1796, in dispatch_request
    return self.ensure_sync(self.view_functions[rule.endpoint])(**view_args)
  File "/Users/lizuckerman/Code/GitHub/packerstacker/app/routes.py", line 209, in search
    questions = questions.union(new_questions).all()
  File "/Applications/anaconda3/lib/python3.9/site-packages/sqlalchemy/orm/query.py", line 2759, in all
    return self._iter().all()
  File "/Applications/anaconda3/lib/python3.9/site-packages/sqlalchemy/orm/query.py", line 2894, in _iter
    result = self.session.execute(
  File "/Applications/anaconda3/lib/python3.9/site-packages/sqlalchemy/orm/session.py", line 1692, in execute
    result = conn._execute_20(statement, params or {}, execution_options)
  File "/Applications/anaconda3/lib/python3.9/site-packages/sqlalchemy/engine/base.py", line 1620, in _execute_20
    return meth(self, args_10style, kwargs_10style, execution_options)
  File "/Applications/anaconda3/lib/python3.9/site-packages/sqlalchemy/sql/elements.py", line 325, in _execute_on_connection
    return connection._execute_clauseelement(
  File "/Applications/anaconda3/lib/python3.9/site-packages/sqlalchemy/engine/base.py", line 1487, in _execute_clauseelement
    ret = self._execute_context(
  File "/Applications/anaconda3/lib/python3.9/site-packages/sqlalchemy/engine/base.py", line 1851, in _execute_context
    self._handle_dbapi_exception(
  File "/Applications/anaconda3/lib/python3.9/site-packages/sqlalchemy/engine/base.py", line 2032, in _handle_dbapi_exception
    util.raise_(
  File "/Applications/anaconda3/lib/python3.9/site-packages/sqlalchemy/util/compat.py", line 207, in raise_
    raise exception
  File "/Applications/anaconda3/lib/python3.9/site-packages/sqlalchemy/engine/base.py", line 1808, in _execute_context
    self.dialect.do_execute(
  File "/Applications/anaconda3/lib/python3.9/site-packages/sqlalchemy/engine/default.py", line 732, in do_execute
    cursor.execute(statement, parameters)
sqlalchemy.exc.OperationalError: (sqlite3.OperationalError) near "UNION": syntax error
[SQL: SELECT anon_1.question_id AS anon_1_question_id, anon_1.question_body AS anon_1_question_body, anon_1.question_timestamp AS anon_1_question_timestamp, anon_1.question_user_id AS anon_1_question_user_id 
FROM ((SELECT question.id AS question_id, question.body AS question_body, question.timestamp AS question_timestamp, question.user_id AS question_user_id 
FROM question JOIN question_tag ON question_tag.question_id = question.id 
WHERE question_tag.tag_id = ? ORDER BY question.timestamp DESC) UNION (SELECT question.id AS question_id, question.body AS question_body, question.timestamp AS question_timestamp, question.user_id AS question_user_id 
FROM question JOIN question_tag ON question_tag.question_id = question.id 
WHERE question_tag.tag_id = ? ORDER BY question.timestamp DESC)) AS anon_1]
[parameters: (1, 2)]
(Background on this error at: https://sqlalche.me/e/14/e3q8)
2023-05-15 14:38:29,545 INFO: Microblog startup [in /Users/kavolkova/Desktop/Code/packerstacker/app/__init__.py:46]
2023-05-18 09:11:36,237 INFO: Microblog startup [in /Users/kavolkova/Desktop/Code/packerstacker/app/__init__.py:46]
2023-05-18 09:14:09,756 INFO: Microblog startup [in /Users/kavolkova/Desktop/Code/packerstacker/app/__init__.py:46]
2023-05-18 09:15:07,021 INFO: Microblog startup [in /Users/kavolkova/Desktop/Code/packerstacker/app/__init__.py:46]
2023-05-18 09:16:49,173 INFO: Microblog startup [in /Users/kavolkova/Desktop/Code/packerstacker/app/__init__.py:46]
2023-05-18 09:18:05,287 INFO: Microblog startup [in /Users/kavolkova/Desktop/Code/packerstacker/app/__init__.py:46]
2023-05-18 09:21:07,034 INFO: Microblog startup [in /Users/kavolkova/Desktop/Code/packerstacker/app/__init__.py:46]
2023-05-18 09:22:47,760 INFO: Microblog startup [in /Users/kavolkova/Desktop/Code/packerstacker/app/__init__.py:46]
2023-05-18 09:24:41,093 INFO: Microblog startup [in /Users/kavolkova/Desktop/Code/packerstacker/app/__init__.py:46]
