2023-03-06 08:39:48,888 ERROR: Exception on /user/bestie [GET] [in /Applications/anaconda3/lib/python3.9/site-packages/flask/app.py:1741]
Traceback (most recent call last):
  File "/Applications/anaconda3/lib/python3.9/site-packages/flask/app.py", line 2525, in wsgi_app
    response = self.full_dispatch_request()
  File "/Applications/anaconda3/lib/python3.9/site-packages/flask/app.py", line 1822, in full_dispatch_request
    rv = self.handle_user_exception(e)
  File "/Applications/anaconda3/lib/python3.9/site-packages/flask/app.py", line 1820, in full_dispatch_request
    rv = self.dispatch_request()
  File "/Applications/anaconda3/lib/python3.9/site-packages/flask/app.py", line 1796, in dispatch_request
    return self.ensure_sync(self.view_functions[rule.endpoint])(**view_args)
  File "/Applications/anaconda3/lib/python3.9/site-packages/flask_login/utils.py", line 290, in decorated_view
    return current_app.ensure_sync(func)(*args, **kwargs)
  File "/Users/lizuckerman/Code/GitHub/packerstacker/app/routes.py", line 88, in user
    return render_template('user.html', user=user, posts=posts.items,
  File "/Applications/anaconda3/lib/python3.9/site-packages/flask/templating.py", line 146, in render_template
    template = app.jinja_env.get_or_select_template(template_name_or_list)
  File "/Applications/anaconda3/lib/python3.9/site-packages/jinja2/environment.py", line 1081, in get_or_select_template
    return self.get_template(template_name_or_list, parent, globals)
  File "/Applications/anaconda3/lib/python3.9/site-packages/jinja2/environment.py", line 1010, in get_template
    return self._load_template(name, globals)
  File "/Applications/anaconda3/lib/python3.9/site-packages/jinja2/environment.py", line 969, in _load_template
    template = self.loader.load(self, name, self.make_globals(globals))
  File "/Applications/anaconda3/lib/python3.9/site-packages/jinja2/loaders.py", line 138, in load
    code = environment.compile(source, name, filename)
  File "/Applications/anaconda3/lib/python3.9/site-packages/jinja2/environment.py", line 768, in compile
    self.handle_exception(source=source_hint)
  File "/Applications/anaconda3/lib/python3.9/site-packages/jinja2/environment.py", line 936, in handle_exception
    raise rewrite_traceback_stack(source=source)
  File "/Users/lizuckerman/Code/GitHub/packerstacker/app/templates/user.html", line 9, in template
    {%if user.type %}<p>{{ *Teacher}}</p>{% endif %}
jinja2.exceptions.TemplateSyntaxError: unexpected '*'
2023-03-06 08:40:40,310 INFO: Microblog startup [in /Users/lizuckerman/Code/GitHub/packerstacker/app/__init__.py:46]
2023-03-06 08:41:22,484 INFO: Microblog startup [in /Users/lizuckerman/Code/GitHub/packerstacker/app/__init__.py:46]
2023-03-06 08:43:11,924 INFO: Microblog startup [in /Users/lizuckerman/Code/GitHub/packerstacker/app/__init__.py:46]
2023-03-06 08:43:52,054 INFO: Microblog startup [in /Users/lizuckerman/Code/GitHub/packerstacker/app/__init__.py:46]
