2023-04-30 17:18:43,114 ERROR: Exception on / [GET] [in /Applications/anaconda3/lib/python3.9/site-packages/flask/app.py:1741]
Traceback (most recent call last):
  File "/Applications/anaconda3/lib/python3.9/site-packages/sqlalchemy/engine/base.py", line 1808, in _execute_context
    self.dialect.do_execute(
  File "/Applications/anaconda3/lib/python3.9/site-packages/sqlalchemy/engine/default.py", line 732, in do_execute
    cursor.execute(statement, parameters)
sqlite3.OperationalError: database is locked

The above exception was the direct cause of the following exception:

Traceback (most recent call last):
  File "/Applications/anaconda3/lib/python3.9/site-packages/flask/app.py", line 2525, in wsgi_app
    response = self.full_dispatch_request()
  File "/Applications/anaconda3/lib/python3.9/site-packages/flask/app.py", line 1822, in full_dispatch_request
    rv = self.handle_user_exception(e)
  File "/Applications/anaconda3/lib/python3.9/site-packages/flask/app.py", line 1818, in full_dispatch_request
    rv = self.preprocess_request()
  File "/Applications/anaconda3/lib/python3.9/site-packages/flask/app.py", line 2309, in preprocess_request
    rv = self.ensure_sync(before_func)()
  File "/Users/lizuckerman/Code/GitHub/packerstacker/app/routes.py", line 17, in before_request
    db.session.commit()
  File "<string>", line 2, in commit
  File "/Applications/anaconda3/lib/python3.9/site-packages/sqlalchemy/orm/session.py", line 1431, in commit
    self._transaction.commit(_to_root=self.future)
  File "/Applications/anaconda3/lib/python3.9/site-packages/sqlalchemy/orm/session.py", line 829, in commit
    self._prepare_impl()
  File "/Applications/anaconda3/lib/python3.9/site-packages/sqlalchemy/orm/session.py", line 808, in _prepare_impl
    self.session.flush()
  File "/Applications/anaconda3/lib/python3.9/site-packages/sqlalchemy/orm/session.py", line 3363, in flush
    self._flush(objects)
  File "/Applications/anaconda3/lib/python3.9/site-packages/sqlalchemy/orm/session.py", line 3503, in _flush
    transaction.rollback(_capture_exception=True)
  File "/Applications/anaconda3/lib/python3.9/site-packages/sqlalchemy/util/langhelpers.py", line 70, in __exit__
    compat.raise_(
  File "/Applications/anaconda3/lib/python3.9/site-packages/sqlalchemy/util/compat.py", line 207, in raise_
    raise exception
  File "/Applications/anaconda3/lib/python3.9/site-packages/sqlalchemy/orm/session.py", line 3463, in _flush
    flush_context.execute()
  File "/Applications/anaconda3/lib/python3.9/site-packages/sqlalchemy/orm/unitofwork.py", line 456, in execute
    rec.execute(self)
  File "/Applications/anaconda3/lib/python3.9/site-packages/sqlalchemy/orm/unitofwork.py", line 630, in execute
    util.preloaded.orm_persistence.save_obj(
  File "/Applications/anaconda3/lib/python3.9/site-packages/sqlalchemy/orm/persistence.py", line 236, in save_obj
    _emit_update_statements(
  File "/Applications/anaconda3/lib/python3.9/site-packages/sqlalchemy/orm/persistence.py", line 1000, in _emit_update_statements
    c = connection._execute_20(
  File "/Applications/anaconda3/lib/python3.9/site-packages/sqlalchemy/engine/base.py", line 1620, in _execute_20
    return meth(self, args_10style, kwargs_10style, execution_options)
  File "/Applications/anaconda3/lib/python3.9/site-packages/sqlalchemy/sql/elements.py", line 325, in _execute_on_connection
    return connection._execute_clauseelement(
  File "/Applications/anaconda3/lib/python3.9/site-packages/sqlalchemy/engine/base.py", line 1487, in _execute_clauseelement
    ret = self._execute_context(
  File "/Applications/anaconda3/lib/python3.9/site-packages/sqlalchemy/engine/base.py", line 1851, in _execute_context
    self._handle_dbapi_exception(
  File "/Applications/anaconda3/lib/python3.9/site-packages/sqlalchemy/engine/base.py", line 2032, in _handle_dbapi_exception
    util.raise_(
  File "/Applications/anaconda3/lib/python3.9/site-packages/sqlalchemy/util/compat.py", line 207, in raise_
    raise exception
  File "/Applications/anaconda3/lib/python3.9/site-packages/sqlalchemy/engine/base.py", line 1808, in _execute_context
    self.dialect.do_execute(
  File "/Applications/anaconda3/lib/python3.9/site-packages/sqlalchemy/engine/default.py", line 732, in do_execute
    cursor.execute(statement, parameters)
sqlalchemy.exc.OperationalError: (sqlite3.OperationalError) database is locked
[SQL: UPDATE user SET last_seen=? WHERE user.id = ?]
[parameters: ('2023-04-30 21:18:37.979434', 1)]
(Background on this error at: https://sqlalche.me/e/14/e3q8)
2023-04-30 17:26:27,086 INFO: Microblog startup [in /Users/lizuckerman/Code/GitHub/packerstacker/app/__init__.py:46]
2023-04-30 17:26:57,853 INFO: Microblog startup [in /Users/lizuckerman/Code/GitHub/packerstacker/app/__init__.py:46]
2023-04-30 17:27:25,270 INFO: Microblog startup [in /Users/lizuckerman/Code/GitHub/packerstacker/app/__init__.py:46]
2023-04-30 17:28:13,618 INFO: Microblog startup [in /Users/lizuckerman/Code/GitHub/packerstacker/app/__init__.py:46]
2023-04-30 17:28:19,540 INFO: Microblog startup [in /Users/lizuckerman/Code/GitHub/packerstacker/app/__init__.py:46]
2023-04-30 17:29:59,218 INFO: Microblog startup [in /Users/lizuckerman/Code/GitHub/packerstacker/app/__init__.py:46]
2023-04-30 17:30:33,162 INFO: Microblog startup [in /Users/lizuckerman/Code/GitHub/packerstacker/app/__init__.py:46]
2023-04-30 17:32:37,427 INFO: Microblog startup [in /Users/lizuckerman/Code/GitHub/packerstacker/app/__init__.py:46]
2023-04-30 17:33:16,785 INFO: Microblog startup [in /Users/lizuckerman/Code/GitHub/packerstacker/app/__init__.py:46]
2023-04-30 17:43:52,924 INFO: Microblog startup [in /Users/lizuckerman/Code/GitHub/packerstacker/app/__init__.py:46]
