2023-04-24 08:46:44,177 INFO: Microblog startup [in /Users/lizuckerman/Code/GitHub/packerstacker/app/__init__.py:46]
2023-04-24 08:47:05,051 INFO: Microblog startup [in /Users/lizuckerman/Code/GitHub/packerstacker/app/__init__.py:46]
2023-04-24 08:47:39,630 INFO: Microblog startup [in /Users/lizuckerman/Code/GitHub/packerstacker/app/__init__.py:46]
2023-04-24 08:47:53,916 INFO: Microblog startup [in /Users/lizuckerman/Code/GitHub/packerstacker/app/__init__.py:46]
2023-04-24 08:47:59,855 INFO: Microblog startup [in /Users/lizuckerman/Code/GitHub/packerstacker/app/__init__.py:46]
2023-04-24 08:56:19,331 INFO: Microblog startup [in /Users/lizuckerman/Code/GitHub/packerstacker/app/__init__.py:46]
2023-04-24 09:04:42,049 INFO: Microblog startup [in /Users/lizuckerman/Code/GitHub/packerstacker/app/__init__.py:46]
2023-04-24 09:04:53,612 INFO: Microblog startup [in /Users/lizuckerman/Code/GitHub/packerstacker/app/__init__.py:46]
2023-04-24 09:05:07,867 INFO: Microblog startup [in /Users/lizuckerman/Code/GitHub/packerstacker/app/__init__.py:46]
2023-04-24 09:05:19,527 INFO: Microblog startup [in /Users/lizuckerman/Code/GitHub/packerstacker/app/__init__.py:46]
2023-04-24 09:06:45,223 INFO: Microblog startup [in /Users/lizuckerman/Code/GitHub/packerstacker/app/__init__.py:46]
2023-04-24 09:06:49,561 INFO: Microblog startup [in /Users/lizuckerman/Code/GitHub/packerstacker/app/__init__.py:46]
2023-04-24 09:06:56,710 INFO: Microblog startup [in /Users/lizuckerman/Code/GitHub/packerstacker/app/__init__.py:46]
2023-04-24 09:09:30,535 INFO: Microblog startup [in /Users/lizuckerman/Code/GitHub/packerstacker/app/__init__.py:46]
2023-04-24 09:17:39,224 INFO: Microblog startup [in /Users/lizuckerman/Code/GitHub/packerstacker/app/__init__.py:46]
2023-04-24 09:20:22,083 INFO: Microblog startup [in /Users/lizuckerman/Code/GitHub/packerstacker/app/__init__.py:46]
2023-04-24 09:20:30,789 INFO: Microblog startup [in /Users/lizuckerman/Code/GitHub/packerstacker/app/__init__.py:46]
2023-04-24 09:20:35,702 INFO: Microblog startup [in /Users/lizuckerman/Code/GitHub/packerstacker/app/__init__.py:46]
2023-04-24 09:20:50,636 INFO: Microblog startup [in /Users/lizuckerman/Code/GitHub/packerstacker/app/__init__.py:46]
2023-04-24 09:21:01,233 ERROR: Exception on / [GET] [in /Applications/anaconda3/lib/python3.9/site-packages/flask/app.py:1741]
Traceback (most recent call last):
  File "/Applications/anaconda3/lib/python3.9/site-packages/flask/app.py", line 2525, in wsgi_app
    response = self.full_dispatch_request()
  File "/Applications/anaconda3/lib/python3.9/site-packages/flask/app.py", line 1822, in full_dispatch_request
    rv = self.handle_user_exception(e)
  File "/Applications/anaconda3/lib/python3.9/site-packages/flask/app.py", line 1818, in full_dispatch_request
    rv = self.preprocess_request()
  File "/Applications/anaconda3/lib/python3.9/site-packages/flask/app.py", line 2309, in preprocess_request
    rv = self.ensure_sync(before_func)()
  File "/Users/lizuckerman/Code/GitHub/packerstacker/app/routes.py", line 14, in before_request
    if current_user.is_authenticated:
  File "/Applications/anaconda3/lib/python3.9/site-packages/werkzeug/local.py", line 316, in __get__
    obj = instance._get_current_object()  # type: ignore[misc]
  File "/Applications/anaconda3/lib/python3.9/site-packages/werkzeug/local.py", line 520, in _get_current_object
    return get_name(local())  # type: ignore
  File "/Applications/anaconda3/lib/python3.9/site-packages/flask_login/utils.py", line 25, in <lambda>
    current_user = LocalProxy(lambda: _get_user())
  File "/Applications/anaconda3/lib/python3.9/site-packages/flask_login/utils.py", line 372, in _get_user
    current_app.login_manager._load_user()
  File "/Applications/anaconda3/lib/python3.9/site-packages/flask_login/login_manager.py", line 364, in _load_user
    user = self._user_callback(user_id)
  File "/Users/lizuckerman/Code/GitHub/packerstacker/app/models.py", line 93, in load_user
    return User.query.get(int(id))
  File "/Applications/anaconda3/lib/python3.9/site-packages/flask_sqlalchemy/model.py", line 30, in __get__
    return cls.query_class(
  File "/Applications/anaconda3/lib/python3.9/site-packages/sqlalchemy/orm/query.py", line 180, in __init__
    self._set_entities(entities)
  File "/Applications/anaconda3/lib/python3.9/site-packages/sqlalchemy/orm/query.py", line 187, in _set_entities
    self._raw_columns = [
  File "/Applications/anaconda3/lib/python3.9/site-packages/sqlalchemy/orm/query.py", line 188, in <listcomp>
    coercions.expect(
  File "/Applications/anaconda3/lib/python3.9/site-packages/sqlalchemy/sql/coercions.py", line 181, in expect
    insp._post_inspect
  File "/Applications/anaconda3/lib/python3.9/site-packages/sqlalchemy/util/langhelpers.py", line 1180, in __get__
    obj.__dict__[self.__name__] = result = self.fget(obj)
  File "/Applications/anaconda3/lib/python3.9/site-packages/sqlalchemy/orm/mapper.py", line 2123, in _post_inspect
    self._check_configure()
  File "/Applications/anaconda3/lib/python3.9/site-packages/sqlalchemy/orm/mapper.py", line 1900, in _check_configure
    _configure_registries({self.registry}, cascade=True)
  File "/Applications/anaconda3/lib/python3.9/site-packages/sqlalchemy/orm/mapper.py", line 3418, in _configure_registries
    _do_configure_registries(registries, cascade)
  File "/Applications/anaconda3/lib/python3.9/site-packages/sqlalchemy/orm/mapper.py", line 3457, in _do_configure_registries
    mapper._post_configure_properties()
  File "/Applications/anaconda3/lib/python3.9/site-packages/sqlalchemy/orm/mapper.py", line 1920, in _post_configure_properties
    prop.post_instrument_class(self)
  File "/Applications/anaconda3/lib/python3.9/site-packages/sqlalchemy/orm/interfaces.py", line 678, in post_instrument_class
    self.strategy.init_class_attribute(mapper)
  File "/Applications/anaconda3/lib/python3.9/site-packages/sqlalchemy/orm/dynamic.py", line 36, in init_class_attribute
    raise exc.InvalidRequestError(
sqlalchemy.exc.InvalidRequestError: On relationship Question.tags, 'dynamic' loaders cannot be used with many-to-one/one-to-one relationships and/or uselist=False.
2023-04-24 09:22:06,520 INFO: Microblog startup [in /Users/lizuckerman/Code/GitHub/packerstacker/app/__init__.py:46]
2023-04-24 09:22:11,370 INFO: Microblog startup [in /Users/lizuckerman/Code/GitHub/packerstacker/app/__init__.py:46]
2023-04-24 09:22:13,974 INFO: Microblog startup [in /Users/lizuckerman/Code/GitHub/packerstacker/app/__init__.py:46]
2023-04-24 09:25:32,319 INFO: Microblog startup [in /Users/lizuckerman/Code/GitHub/packerstacker/app/__init__.py:46]
2023-04-25 10:35:33,728 INFO: Microblog startup [in /Users/lizuckerman/Code/GitHub/packerstacker/app/__init__.py:46]
2023-04-25 10:44:53,659 INFO: Microblog startup [in /Users/lizuckerman/Code/GitHub/packerstacker/app/__init__.py:46]
2023-04-25 10:57:38,992 INFO: Microblog startup [in /Users/lizuckerman/Code/GitHub/packerstacker/app/__init__.py:46]
2023-04-25 11:02:32,642 INFO: Microblog startup [in /Users/lizuckerman/Code/GitHub/packerstacker/app/__init__.py:46]
2023-04-25 11:05:58,808 INFO: Microblog startup [in /Users/lizuckerman/Code/GitHub/packerstacker/app/__init__.py:46]
2023-04-25 11:06:27,427 ERROR: Exception on / [POST] [in /Applications/anaconda3/lib/python3.9/site-packages/flask/app.py:1741]
Traceback (most recent call last):
  File "/Applications/anaconda3/lib/python3.9/site-packages/flask/app.py", line 2525, in wsgi_app
    response = self.full_dispatch_request()
  File "/Applications/anaconda3/lib/python3.9/site-packages/flask/app.py", line 1822, in full_dispatch_request
    rv = self.handle_user_exception(e)
  File "/Applications/anaconda3/lib/python3.9/site-packages/flask/app.py", line 1820, in full_dispatch_request
    rv = self.dispatch_request()
  File "/Applications/anaconda3/lib/python3.9/site-packages/flask/app.py", line 1796, in dispatch_request
    return self.ensure_sync(self.view_functions[rule.endpoint])(**view_args)
  File "/Applications/anaconda3/lib/python3.9/site-packages/flask_login/utils.py", line 290, in decorated_view
    return current_app.ensure_sync(func)(*args, **kwargs)
  File "/Users/lizuckerman/Code/GitHub/packerstacker/app/routes.py", line 24, in index
    question = Question(body=form.question.data, author=current_user, tags=form.tags.data)
  File "<string>", line 4, in __init__
  File "/Applications/anaconda3/lib/python3.9/site-packages/sqlalchemy/orm/state.py", line 480, in _initialize_instance
    manager.dispatch.init_failure(self, args, kwargs)
  File "/Applications/anaconda3/lib/python3.9/site-packages/sqlalchemy/util/langhelpers.py", line 70, in __exit__
    compat.raise_(
  File "/Applications/anaconda3/lib/python3.9/site-packages/sqlalchemy/util/compat.py", line 207, in raise_
    raise exception
  File "/Applications/anaconda3/lib/python3.9/site-packages/sqlalchemy/orm/state.py", line 477, in _initialize_instance
    return manager.original_init(*mixed[1:], **kwargs)
  File "/Applications/anaconda3/lib/python3.9/site-packages/sqlalchemy/orm/decl_base.py", line 1157, in _declarative_constructor
    setattr(self, k, kwargs[k])
  File "/Applications/anaconda3/lib/python3.9/site-packages/sqlalchemy/orm/attributes.py", line 459, in __set__
    self.impl.set(
  File "/Applications/anaconda3/lib/python3.9/site-packages/sqlalchemy/orm/attributes.py", line 1268, in set
    value = self.fire_replace_event(state, dict_, value, old, initiator)
  File "/Applications/anaconda3/lib/python3.9/site-packages/sqlalchemy/orm/attributes.py", line 1294, in fire_replace_event
    value = fn(
  File "/Applications/anaconda3/lib/python3.9/site-packages/sqlalchemy/orm/unitofwork.py", line 119, in set_
    newvalue_state = attributes.instance_state(newvalue)
AttributeError: 'str' object has no attribute '_sa_instance_state'
2023-04-25 11:09:33,858 INFO: Microblog startup [in /Users/lizuckerman/Code/GitHub/packerstacker/app/__init__.py:46]
