2023-04-05 11:08:03,489 ERROR: Exception on /q/2 [GET] [in /Applications/anaconda3/lib/python3.9/site-packages/flask/app.py:1741]
Traceback (most recent call last):
  File "/Applications/anaconda3/lib/python3.9/site-packages/flask/app.py", line 2525, in wsgi_app
    response = self.full_dispatch_request()
  File "/Applications/anaconda3/lib/python3.9/site-packages/flask/app.py", line 1822, in full_dispatch_request
    rv = self.handle_user_exception(e)
  File "/Applications/anaconda3/lib/python3.9/site-packages/flask/app.py", line 1820, in full_dispatch_request
    rv = self.dispatch_request()
  File "/Applications/anaconda3/lib/python3.9/site-packages/flask/app.py", line 1796, in dispatch_request
    return self.ensure_sync(self.view_functions[rule.endpoint])(**view_args)
  File "/Users/lizuckerman/Code/GitHub/packerstacker/app/routes.py", line 163, in question_page
    return render_template("question_page.html", title='Question', form=form, question=question)
  File "/Applications/anaconda3/lib/python3.9/site-packages/flask/templating.py", line 146, in render_template
    template = app.jinja_env.get_or_select_template(template_name_or_list)
  File "/Applications/anaconda3/lib/python3.9/site-packages/jinja2/environment.py", line 1081, in get_or_select_template
    return self.get_template(template_name_or_list, parent, globals)
  File "/Applications/anaconda3/lib/python3.9/site-packages/jinja2/environment.py", line 1010, in get_template
    return self._load_template(name, globals)
  File "/Applications/anaconda3/lib/python3.9/site-packages/jinja2/environment.py", line 969, in _load_template
    template = self.loader.load(self, name, self.make_globals(globals))
  File "/Applications/anaconda3/lib/python3.9/site-packages/jinja2/loaders.py", line 138, in load
    code = environment.compile(source, name, filename)
  File "/Applications/anaconda3/lib/python3.9/site-packages/jinja2/environment.py", line 768, in compile
    self.handle_exception(source=source_hint)
  File "/Applications/anaconda3/lib/python3.9/site-packages/jinja2/environment.py", line 936, in handle_exception
    raise rewrite_traceback_stack(source=source)
  File "/Users/lizuckerman/Code/GitHub/packerstacker/app/templates/question_page.html", line 11, in template
    {% block app_content %}
jinja2.exceptions.TemplateAssertionError: block 'app_content' defined twice
2023-04-05 11:08:17,712 INFO: Microblog startup [in /Users/lizuckerman/Code/GitHub/packerstacker/app/__init__.py:46]
2023-04-05 11:09:23,041 INFO: Microblog startup [in /Users/lizuckerman/Code/GitHub/packerstacker/app/__init__.py:46]
2023-04-05 11:10:22,186 INFO: Microblog startup [in /Users/lizuckerman/Code/GitHub/packerstacker/app/__init__.py:46]
2023-04-05 11:10:33,313 ERROR: Exception on /q/2 [POST] [in /Applications/anaconda3/lib/python3.9/site-packages/flask/app.py:1741]
Traceback (most recent call last):
  File "/Applications/anaconda3/lib/python3.9/site-packages/flask/app.py", line 2525, in wsgi_app
    response = self.full_dispatch_request()
  File "/Applications/anaconda3/lib/python3.9/site-packages/flask/app.py", line 1822, in full_dispatch_request
    rv = self.handle_user_exception(e)
  File "/Applications/anaconda3/lib/python3.9/site-packages/flask/app.py", line 1820, in full_dispatch_request
    rv = self.dispatch_request()
  File "/Applications/anaconda3/lib/python3.9/site-packages/flask/app.py", line 1796, in dispatch_request
    return self.ensure_sync(self.view_functions[rule.endpoint])(**view_args)
  File "/Users/lizuckerman/Code/GitHub/packerstacker/app/routes.py", line 160, in question_page
    reply = Reply(body=form.reply.data, author=current_user, op=question)
NameError: name 'Reply' is not defined
2023-04-05 11:11:11,510 INFO: Microblog startup [in /Users/lizuckerman/Code/GitHub/packerstacker/app/__init__.py:46]
2023-04-05 11:13:57,491 INFO: Microblog startup [in /Users/lizuckerman/Code/GitHub/packerstacker/app/__init__.py:46]
2023-04-05 11:14:02,247 ERROR: Exception on /q/2 [GET] [in /Applications/anaconda3/lib/python3.9/site-packages/flask/app.py:1741]
Traceback (most recent call last):
  File "/Applications/anaconda3/lib/python3.9/site-packages/flask/app.py", line 2525, in wsgi_app
    response = self.full_dispatch_request()
  File "/Applications/anaconda3/lib/python3.9/site-packages/flask/app.py", line 1822, in full_dispatch_request
    rv = self.handle_user_exception(e)
  File "/Applications/anaconda3/lib/python3.9/site-packages/flask/app.py", line 1820, in full_dispatch_request
    rv = self.dispatch_request()
  File "/Applications/anaconda3/lib/python3.9/site-packages/flask/app.py", line 1796, in dispatch_request
    return self.ensure_sync(self.view_functions[rule.endpoint])(**view_args)
  File "/Users/lizuckerman/Code/GitHub/packerstacker/app/routes.py", line 165, in question_page
    replies = question.replies().paginate(
TypeError: 'AppenderQuery' object is not callable
2023-04-05 11:17:32,660 INFO: Microblog startup [in /Users/lizuckerman/Code/GitHub/packerstacker/app/__init__.py:46]
2023-04-05 11:17:40,069 INFO: Microblog startup [in /Users/lizuckerman/Code/GitHub/packerstacker/app/__init__.py:46]
2023-04-05 11:17:44,711 INFO: Microblog startup [in /Users/lizuckerman/Code/GitHub/packerstacker/app/__init__.py:46]
2023-04-05 11:17:50,944 ERROR: Exception on /q/2 [GET] [in /Applications/anaconda3/lib/python3.9/site-packages/flask/app.py:1741]
Traceback (most recent call last):
  File "/Applications/anaconda3/lib/python3.9/site-packages/flask/app.py", line 2525, in wsgi_app
    response = self.full_dispatch_request()
  File "/Applications/anaconda3/lib/python3.9/site-packages/flask/app.py", line 1822, in full_dispatch_request
    rv = self.handle_user_exception(e)
  File "/Applications/anaconda3/lib/python3.9/site-packages/flask/app.py", line 1820, in full_dispatch_request
    rv = self.dispatch_request()
  File "/Applications/anaconda3/lib/python3.9/site-packages/flask/app.py", line 1796, in dispatch_request
    return self.ensure_sync(self.view_functions[rule.endpoint])(**view_args)
  File "/Users/lizuckerman/Code/GitHub/packerstacker/app/routes.py", line 165, in question_page
    replies = question.replies().paginate(
TypeError: 'AppenderQuery' object is not callable
2023-04-05 11:19:37,404 INFO: Microblog startup [in /Users/lizuckerman/Code/GitHub/packerstacker/app/__init__.py:46]
2023-04-05 11:19:43,290 ERROR: Exception on /q/2 [GET] [in /Applications/anaconda3/lib/python3.9/site-packages/flask/app.py:1741]
Traceback (most recent call last):
  File "/Applications/anaconda3/lib/python3.9/site-packages/flask/app.py", line 2525, in wsgi_app
    response = self.full_dispatch_request()
  File "/Applications/anaconda3/lib/python3.9/site-packages/flask/app.py", line 1822, in full_dispatch_request
    rv = self.handle_user_exception(e)
  File "/Applications/anaconda3/lib/python3.9/site-packages/flask/app.py", line 1820, in full_dispatch_request
    rv = self.dispatch_request()
  File "/Applications/anaconda3/lib/python3.9/site-packages/flask/app.py", line 1796, in dispatch_request
    return self.ensure_sync(self.view_functions[rule.endpoint])(**view_args)
  File "/Users/lizuckerman/Code/GitHub/packerstacker/app/routes.py", line 165, in question_page
    replies = question.replies().paginate(
TypeError: 'AppenderQuery' object is not callable
2023-04-05 11:21:49,903 INFO: Microblog startup [in /Users/lizuckerman/Code/GitHub/packerstacker/app/__init__.py:46]
2023-04-05 11:22:00,526 ERROR: Exception on /q/2 [POST] [in /Applications/anaconda3/lib/python3.9/site-packages/flask/app.py:1741]
Traceback (most recent call last):
  File "/Applications/anaconda3/lib/python3.9/site-packages/flask/app.py", line 2525, in wsgi_app
    response = self.full_dispatch_request()
  File "/Applications/anaconda3/lib/python3.9/site-packages/flask/app.py", line 1822, in full_dispatch_request
    rv = self.handle_user_exception(e)
  File "/Applications/anaconda3/lib/python3.9/site-packages/flask/app.py", line 1820, in full_dispatch_request
    rv = self.dispatch_request()
  File "/Applications/anaconda3/lib/python3.9/site-packages/flask/app.py", line 1796, in dispatch_request
    return self.ensure_sync(self.view_functions[rule.endpoint])(**view_args)
  File "/Users/lizuckerman/Code/GitHub/packerstacker/app/routes.py", line 163, in question_page
    redirect(url_for('q/<id>'))
  File "/Applications/anaconda3/lib/python3.9/site-packages/flask/helpers.py", line 256, in url_for
    return current_app.url_for(
  File "/Applications/anaconda3/lib/python3.9/site-packages/flask/app.py", line 2031, in url_for
    return self.handle_url_build_error(error, endpoint, values)
  File "/Applications/anaconda3/lib/python3.9/site-packages/flask/app.py", line 2020, in url_for
    rv = url_adapter.build(  # type: ignore[union-attr]
  File "/Applications/anaconda3/lib/python3.9/site-packages/werkzeug/routing/map.py", line 917, in build
    raise BuildError(endpoint, values, method, self)
werkzeug.routing.exceptions.BuildError: Could not build url for endpoint 'q/<id>'. Did you mean 'index' instead?
2023-04-05 11:22:48,352 INFO: Microblog startup [in /Users/lizuckerman/Code/GitHub/packerstacker/app/__init__.py:46]
