2023-04-28 11:49:30,965 ERROR: Exception on / [GET] [in /Applications/anaconda3/lib/python3.9/site-packages/flask/app.py:1741]
Traceback (most recent call last):
  File "/Applications/anaconda3/lib/python3.9/site-packages/flask/app.py", line 2525, in wsgi_app
    response = self.full_dispatch_request()
  File "/Applications/anaconda3/lib/python3.9/site-packages/flask/app.py", line 1822, in full_dispatch_request
    rv = self.handle_user_exception(e)
  File "/Applications/anaconda3/lib/python3.9/site-packages/flask/app.py", line 1820, in full_dispatch_request
    rv = self.dispatch_request()
  File "/Applications/anaconda3/lib/python3.9/site-packages/flask/app.py", line 1796, in dispatch_request
    return self.ensure_sync(self.view_functions[rule.endpoint])(**view_args)
  File "/Applications/anaconda3/lib/python3.9/site-packages/flask_login/utils.py", line 290, in decorated_view
    return current_app.ensure_sync(func)(*args, **kwargs)
  File "/Users/lizuckerman/Code/GitHub/packerstacker/app/routes.py", line 46, in index
    return render_template('index.html', title='Home', form=form,
  File "/Applications/anaconda3/lib/python3.9/site-packages/flask/templating.py", line 147, in render_template
    return _render(app, template, context)
  File "/Applications/anaconda3/lib/python3.9/site-packages/flask/templating.py", line 130, in _render
    rv = template.render(context)
  File "/Applications/anaconda3/lib/python3.9/site-packages/jinja2/environment.py", line 1301, in render
    self.environment.handle_exception()
  File "/Applications/anaconda3/lib/python3.9/site-packages/jinja2/environment.py", line 936, in handle_exception
    raise rewrite_traceback_stack(source=source)
  File "/Users/lizuckerman/Code/GitHub/packerstacker/app/templates/index.html", line 2, in top-level template code
    {% import 'bootstrap/wtf.html' as wtf %}
  File "/Users/lizuckerman/Code/GitHub/packerstacker/app/templates/base.html", line 1, in top-level template code
    {% extends 'bootstrap/base.html' %}
  File "/Applications/anaconda3/lib/python3.9/site-packages/flask_bootstrap/templates/bootstrap/base.html", line 1, in top-level template code
    {% block doc -%}
  File "/Applications/anaconda3/lib/python3.9/site-packages/flask_bootstrap/templates/bootstrap/base.html", line 4, in block 'doc'
    {%- block html %}
  File "/Applications/anaconda3/lib/python3.9/site-packages/flask_bootstrap/templates/bootstrap/base.html", line 20, in block 'html'
    {% block body -%}
  File "/Applications/anaconda3/lib/python3.9/site-packages/flask_bootstrap/templates/bootstrap/base.html", line 23, in block 'body'
    {% block content -%}
  File "/Users/lizuckerman/Code/GitHub/packerstacker/app/templates/base.html", line 52, in block 'content'
    {% block app_content %}{% endblock %}
  File "/Users/lizuckerman/Code/GitHub/packerstacker/app/templates/index.html", line 11, in block 'app_content'
    {% include '_question.html' %}
  File "/Users/lizuckerman/Code/GitHub/packerstacker/app/templates/_question.html", line 17, in top-level template code
    <a href="{{ url_for('tag', id=tag.id) }}">
  File "/Applications/anaconda3/lib/python3.9/site-packages/flask/app.py", line 2031, in url_for
    return self.handle_url_build_error(error, endpoint, values)
  File "/Applications/anaconda3/lib/python3.9/site-packages/flask/app.py", line 2020, in url_for
    rv = url_adapter.build(  # type: ignore[union-attr]
  File "/Applications/anaconda3/lib/python3.9/site-packages/werkzeug/routing/map.py", line 917, in build
    raise BuildError(endpoint, values, method, self)
werkzeug.routing.exceptions.BuildError: Could not build url for endpoint 'tag' with values ['id']. Did you mean 'tag_page' instead?
2023-04-28 11:51:24,886 INFO: Microblog startup [in /Users/lizuckerman/Code/GitHub/packerstacker/app/__init__.py:46]
2023-04-28 11:51:29,996 ERROR: Exception on /tag/2 [GET] [in /Applications/anaconda3/lib/python3.9/site-packages/flask/app.py:1741]
Traceback (most recent call last):
  File "/Applications/anaconda3/lib/python3.9/site-packages/flask/app.py", line 2525, in wsgi_app
    response = self.full_dispatch_request()
  File "/Applications/anaconda3/lib/python3.9/site-packages/flask/app.py", line 1822, in full_dispatch_request
    rv = self.handle_user_exception(e)
  File "/Applications/anaconda3/lib/python3.9/site-packages/flask/app.py", line 1820, in full_dispatch_request
    rv = self.dispatch_request()
  File "/Applications/anaconda3/lib/python3.9/site-packages/flask/app.py", line 1796, in dispatch_request
    return self.ensure_sync(self.view_functions[rule.endpoint])(**view_args)
  File "/Users/lizuckerman/Code/GitHub/packerstacker/app/routes.py", line 189, in tag_page
    questions = tag.questions.order_by(Question.timestamp.desc()).paginate(
AttributeError: 'BaseQuery' object has no attribute 'questions'
2023-04-28 11:53:26,040 INFO: Microblog startup [in /Users/lizuckerman/Code/GitHub/packerstacker/app/__init__.py:46]
2023-04-28 11:53:34,023 ERROR: Exception on /tag/1 [GET] [in /Applications/anaconda3/lib/python3.9/site-packages/flask/app.py:1741]
Traceback (most recent call last):
  File "/Applications/anaconda3/lib/python3.9/site-packages/flask/app.py", line 2525, in wsgi_app
    response = self.full_dispatch_request()
  File "/Applications/anaconda3/lib/python3.9/site-packages/flask/app.py", line 1822, in full_dispatch_request
    rv = self.handle_user_exception(e)
  File "/Applications/anaconda3/lib/python3.9/site-packages/flask/app.py", line 1820, in full_dispatch_request
    rv = self.dispatch_request()
  File "/Applications/anaconda3/lib/python3.9/site-packages/flask/app.py", line 1796, in dispatch_request
    return self.ensure_sync(self.view_functions[rule.endpoint])(**view_args)
  File "/Users/lizuckerman/Code/GitHub/packerstacker/app/routes.py", line 189, in tag_page
    print(tag.questions)
AttributeError: 'BaseQuery' object has no attribute 'questions'
2023-04-28 11:58:02,144 INFO: Microblog startup [in /Users/lizuckerman/Code/GitHub/packerstacker/app/__init__.py:46]
2023-04-28 11:58:10,175 ERROR: Exception on /tag/1 [GET] [in /Applications/anaconda3/lib/python3.9/site-packages/flask/app.py:1741]
Traceback (most recent call last):
  File "/Applications/anaconda3/lib/python3.9/site-packages/flask/app.py", line 2525, in wsgi_app
    response = self.full_dispatch_request()
  File "/Applications/anaconda3/lib/python3.9/site-packages/flask/app.py", line 1822, in full_dispatch_request
    rv = self.handle_user_exception(e)
  File "/Applications/anaconda3/lib/python3.9/site-packages/flask/app.py", line 1820, in full_dispatch_request
    rv = self.dispatch_request()
  File "/Applications/anaconda3/lib/python3.9/site-packages/flask/app.py", line 1796, in dispatch_request
    return self.ensure_sync(self.view_functions[rule.endpoint])(**view_args)
  File "/Users/lizuckerman/Code/GitHub/packerstacker/app/routes.py", line 189, in tag_page
    questions = tag.tag_questions().paginate(
AttributeError: 'BaseQuery' object has no attribute 'tag_questions'
2023-04-28 11:59:21,527 INFO: Microblog startup [in /Users/lizuckerman/Code/GitHub/packerstacker/app/__init__.py:46]
2023-04-28 12:02:58,716 INFO: Microblog startup [in /Users/lizuckerman/Code/GitHub/packerstacker/app/__init__.py:46]
2023-04-28 12:07:10,181 INFO: Microblog startup [in /Users/lizuckerman/Code/GitHub/packerstacker/app/__init__.py:46]
2023-04-28 12:09:24,608 INFO: Microblog startup [in /Users/lizuckerman/Code/GitHub/packerstacker/app/__init__.py:46]
2023-04-28 12:09:49,580 INFO: Microblog startup [in /Users/lizuckerman/Code/GitHub/packerstacker/app/__init__.py:46]
2023-04-28 12:11:07,319 INFO: Microblog startup [in /Users/lizuckerman/Code/GitHub/packerstacker/app/__init__.py:46]
2023-04-28 12:11:42,034 INFO: Microblog startup [in /Users/lizuckerman/Code/GitHub/packerstacker/app/__init__.py:46]
2023-04-28 12:12:56,992 INFO: Microblog startup [in /Users/lizuckerman/Code/GitHub/packerstacker/app/__init__.py:46]
2023-04-28 12:13:19,100 INFO: Microblog startup [in /Users/lizuckerman/Code/GitHub/packerstacker/app/__init__.py:46]
2023-04-28 12:15:57,546 INFO: Microblog startup [in /Users/lizuckerman/Code/GitHub/packerstacker/app/__init__.py:46]
2023-04-28 12:16:02,545 ERROR: Exception on /explore [GET] [in /Applications/anaconda3/lib/python3.9/site-packages/flask/app.py:1741]
Traceback (most recent call last):
  File "/Applications/anaconda3/lib/python3.9/site-packages/flask/app.py", line 2525, in wsgi_app
    response = self.full_dispatch_request()
  File "/Applications/anaconda3/lib/python3.9/site-packages/flask/app.py", line 1822, in full_dispatch_request
    rv = self.handle_user_exception(e)
  File "/Applications/anaconda3/lib/python3.9/site-packages/flask/app.py", line 1820, in full_dispatch_request
    rv = self.dispatch_request()
  File "/Applications/anaconda3/lib/python3.9/site-packages/flask/app.py", line 1796, in dispatch_request
    return self.ensure_sync(self.view_functions[rule.endpoint])(**view_args)
  File "/Users/lizuckerman/Code/GitHub/packerstacker/app/routes.py", line 163, in explore
    return render_template("index.html", title='Explore', tags=tags.items, questions=questions.items,next_url=next_url, prev_url=prev_url)
AttributeError: 'list' object has no attribute 'items'
2023-04-28 12:16:21,118 INFO: Microblog startup [in /Users/lizuckerman/Code/GitHub/packerstacker/app/__init__.py:46]
2023-04-28 12:17:23,836 INFO: Microblog startup [in /Users/lizuckerman/Code/GitHub/packerstacker/app/__init__.py:46]
2023-04-28 12:22:04,879 INFO: Microblog startup [in /Users/lizuckerman/Code/GitHub/packerstacker/app/__init__.py:46]
2023-04-28 12:23:47,302 INFO: Microblog startup [in /Users/lizuckerman/Code/GitHub/packerstacker/app/__init__.py:46]
2023-04-28 12:24:10,918 INFO: Microblog startup [in /Users/lizuckerman/Code/GitHub/packerstacker/app/__init__.py:46]
2023-04-28 12:24:54,388 INFO: Microblog startup [in /Users/lizuckerman/Code/GitHub/packerstacker/app/__init__.py:46]
2023-04-28 13:11:43,072 INFO: Microblog startup [in /Users/lizuckerman/Code/GitHub/packerstacker/app/__init__.py:46]
2023-04-28 13:12:54,145 INFO: Microblog startup [in /Users/lizuckerman/Code/GitHub/packerstacker/app/__init__.py:46]
