2023-04-27 15:00:45,951 ERROR: Exception on /favicon.ico [GET] [in /Users/gbenedisgrab/Code/packerstacker/venv/lib/python3.10/site-packages/flask/app.py:1414]
Traceback (most recent call last):
  File "/Users/gbenedisgrab/Code/packerstacker/venv/lib/python3.10/site-packages/flask/app.py", line 2190, in wsgi_app
    response = self.full_dispatch_request()
  File "/Users/gbenedisgrab/Code/packerstacker/venv/lib/python3.10/site-packages/flask/app.py", line 1486, in full_dispatch_request
    rv = self.handle_user_exception(e)
  File "/Users/gbenedisgrab/Code/packerstacker/venv/lib/python3.10/site-packages/flask/app.py", line 1482, in full_dispatch_request
    rv = self.preprocess_request()
  File "/Users/gbenedisgrab/Code/packerstacker/venv/lib/python3.10/site-packages/flask/app.py", line 1974, in preprocess_request
    rv = self.ensure_sync(before_func)()
  File "/Users/gbenedisgrab/Code/packerstacker/app/routes.py", line 14, in before_request
    if current_user.is_authenticated:
  File "/Users/gbenedisgrab/Code/packerstacker/venv/lib/python3.10/site-packages/werkzeug/local.py", line 311, in __get__
    obj = instance._get_current_object()
  File "/Users/gbenedisgrab/Code/packerstacker/venv/lib/python3.10/site-packages/werkzeug/local.py", line 515, in _get_current_object
    return get_name(local())  # type: ignore
  File "/Users/gbenedisgrab/Code/packerstacker/venv/lib/python3.10/site-packages/flask_login/utils.py", line 25, in <lambda>
    current_user = LocalProxy(lambda: _get_user())
  File "/Users/gbenedisgrab/Code/packerstacker/venv/lib/python3.10/site-packages/flask_login/utils.py", line 372, in _get_user
    current_app.login_manager._load_user()
  File "/Users/gbenedisgrab/Code/packerstacker/venv/lib/python3.10/site-packages/flask_login/login_manager.py", line 364, in _load_user
    user = self._user_callback(user_id)
  File "/Users/gbenedisgrab/Code/packerstacker/app/models.py", line 98, in load_user
    return User.query.get(int(id))
  File "/Users/gbenedisgrab/Code/packerstacker/venv/lib/python3.10/site-packages/flask_sqlalchemy/model.py", line 30, in __get__
    return cls.query_class(
  File "/Users/gbenedisgrab/Code/packerstacker/venv/lib/python3.10/site-packages/sqlalchemy/orm/query.py", line 273, in __init__
    self._set_entities(entities)
  File "/Users/gbenedisgrab/Code/packerstacker/venv/lib/python3.10/site-packages/sqlalchemy/orm/query.py", line 282, in _set_entities
    self._raw_columns = [
  File "/Users/gbenedisgrab/Code/packerstacker/venv/lib/python3.10/site-packages/sqlalchemy/orm/query.py", line 283, in <listcomp>
    coercions.expect(
  File "/Users/gbenedisgrab/Code/packerstacker/venv/lib/python3.10/site-packages/sqlalchemy/sql/coercions.py", line 406, in expect
    insp._post_inspect
  File "/Users/gbenedisgrab/Code/packerstacker/venv/lib/python3.10/site-packages/sqlalchemy/util/langhelpers.py", line 1257, in __get__
    obj.__dict__[self.__name__] = result = self.fget(obj)
  File "/Users/gbenedisgrab/Code/packerstacker/venv/lib/python3.10/site-packages/sqlalchemy/orm/mapper.py", line 2681, in _post_inspect
    self._check_configure()
  File "/Users/gbenedisgrab/Code/packerstacker/venv/lib/python3.10/site-packages/sqlalchemy/orm/mapper.py", line 2362, in _check_configure
    _configure_registries({self.registry}, cascade=True)
  File "/Users/gbenedisgrab/Code/packerstacker/venv/lib/python3.10/site-packages/sqlalchemy/orm/mapper.py", line 4177, in _configure_registries
    _do_configure_registries(registries, cascade)
  File "/Users/gbenedisgrab/Code/packerstacker/venv/lib/python3.10/site-packages/sqlalchemy/orm/mapper.py", line 4215, in _do_configure_registries
    raise e
sqlalchemy.exc.InvalidRequestError: One or more mappers failed to initialize - can't proceed with initialization of other mappers. Triggering mapper: 'Mapper[Question(question)]'. Original exception was: Error creating backref 'questions' on relationship 'Question.tags': property of that name exists on mapper 'Mapper[Tag(tag)]'
2023-04-27 15:01:00,742 INFO: Microblog startup [in /Users/gbenedisgrab/Code/packerstacker/app/__init__.py:46]
2023-04-27 15:02:45,904 INFO: Microblog startup [in /Users/gbenedisgrab/Code/packerstacker/app/__init__.py:46]
2023-04-27 15:02:50,707 ERROR: Exception on / [GET] [in /Users/gbenedisgrab/Code/packerstacker/venv/lib/python3.10/site-packages/flask/app.py:1414]
Traceback (most recent call last):
  File "/Users/gbenedisgrab/Code/packerstacker/venv/lib/python3.10/site-packages/flask/app.py", line 2190, in wsgi_app
    response = self.full_dispatch_request()
  File "/Users/gbenedisgrab/Code/packerstacker/venv/lib/python3.10/site-packages/flask/app.py", line 1486, in full_dispatch_request
    rv = self.handle_user_exception(e)
  File "/Users/gbenedisgrab/Code/packerstacker/venv/lib/python3.10/site-packages/flask/app.py", line 1482, in full_dispatch_request
    rv = self.preprocess_request()
  File "/Users/gbenedisgrab/Code/packerstacker/venv/lib/python3.10/site-packages/flask/app.py", line 1974, in preprocess_request
    rv = self.ensure_sync(before_func)()
  File "/Users/gbenedisgrab/Code/packerstacker/app/routes.py", line 14, in before_request
    if current_user.is_authenticated:
  File "/Users/gbenedisgrab/Code/packerstacker/venv/lib/python3.10/site-packages/werkzeug/local.py", line 311, in __get__
    obj = instance._get_current_object()
  File "/Users/gbenedisgrab/Code/packerstacker/venv/lib/python3.10/site-packages/werkzeug/local.py", line 515, in _get_current_object
    return get_name(local())  # type: ignore
  File "/Users/gbenedisgrab/Code/packerstacker/venv/lib/python3.10/site-packages/flask_login/utils.py", line 25, in <lambda>
    current_user = LocalProxy(lambda: _get_user())
  File "/Users/gbenedisgrab/Code/packerstacker/venv/lib/python3.10/site-packages/flask_login/utils.py", line 372, in _get_user
    current_app.login_manager._load_user()
  File "/Users/gbenedisgrab/Code/packerstacker/venv/lib/python3.10/site-packages/flask_login/login_manager.py", line 364, in _load_user
    user = self._user_callback(user_id)
  File "/Users/gbenedisgrab/Code/packerstacker/app/models.py", line 98, in load_user
    return User.query.get(int(id))
  File "/Users/gbenedisgrab/Code/packerstacker/venv/lib/python3.10/site-packages/flask_sqlalchemy/model.py", line 30, in __get__
    return cls.query_class(
  File "/Users/gbenedisgrab/Code/packerstacker/venv/lib/python3.10/site-packages/sqlalchemy/orm/query.py", line 273, in __init__
    self._set_entities(entities)
  File "/Users/gbenedisgrab/Code/packerstacker/venv/lib/python3.10/site-packages/sqlalchemy/orm/query.py", line 282, in _set_entities
    self._raw_columns = [
  File "/Users/gbenedisgrab/Code/packerstacker/venv/lib/python3.10/site-packages/sqlalchemy/orm/query.py", line 283, in <listcomp>
    coercions.expect(
  File "/Users/gbenedisgrab/Code/packerstacker/venv/lib/python3.10/site-packages/sqlalchemy/sql/coercions.py", line 406, in expect
    insp._post_inspect
  File "/Users/gbenedisgrab/Code/packerstacker/venv/lib/python3.10/site-packages/sqlalchemy/util/langhelpers.py", line 1257, in __get__
    obj.__dict__[self.__name__] = result = self.fget(obj)
  File "/Users/gbenedisgrab/Code/packerstacker/venv/lib/python3.10/site-packages/sqlalchemy/orm/mapper.py", line 2681, in _post_inspect
    self._check_configure()
  File "/Users/gbenedisgrab/Code/packerstacker/venv/lib/python3.10/site-packages/sqlalchemy/orm/mapper.py", line 2362, in _check_configure
    _configure_registries({self.registry}, cascade=True)
  File "/Users/gbenedisgrab/Code/packerstacker/venv/lib/python3.10/site-packages/sqlalchemy/orm/mapper.py", line 4177, in _configure_registries
    _do_configure_registries(registries, cascade)
  File "/Users/gbenedisgrab/Code/packerstacker/venv/lib/python3.10/site-packages/sqlalchemy/orm/mapper.py", line 4219, in _do_configure_registries
    mapper._post_configure_properties()
  File "/Users/gbenedisgrab/Code/packerstacker/venv/lib/python3.10/site-packages/sqlalchemy/orm/mapper.py", line 2379, in _post_configure_properties
    prop.init()
  File "/Users/gbenedisgrab/Code/packerstacker/venv/lib/python3.10/site-packages/sqlalchemy/orm/interfaces.py", line 549, in init
    self.do_init()
  File "/Users/gbenedisgrab/Code/packerstacker/venv/lib/python3.10/site-packages/sqlalchemy/orm/relationships.py", line 1637, in do_init
    self._generate_backref()
  File "/Users/gbenedisgrab/Code/packerstacker/venv/lib/python3.10/site-packages/sqlalchemy/orm/relationships.py", line 2070, in _generate_backref
    raise sa_exc.ArgumentError(
sqlalchemy.exc.ArgumentError: Error creating backref 'questions' on relationship 'Question.tags': property of that name exists on mapper 'Mapper[Tag(tag)]'
